Workbook

Sheet Свод потребности
A1: Потребность на коэффициент плотности для ПМСП по регионам при действующем БКПН (приказ № 170), тыс. тенге в год
A3: Регион | B3: Прикреплённое население (РПН 01.08.2026) | C3: Расходы при Кплотн по приказу № 170 | D3: Расходы при Кплотн по приказу № 309 | E3: Потребность | F3: %
A4: Акмолинская область | B4: =SUMIFS(Моделирование!$E$8:$E$219,Моделирование!$B$8:$B$219,$A4) -> 773511 | C4: =SUMIFS(Моделирование!$H$8:$H$219,Моделирование!$B$8:$B$219,$A4) -> 20572959 | D4: =SUMIFS(Моделирование!$I$8:$I$219,Моделирование!$B$8:$B$219,$A4) -> 23398055 | E4: =D4-C4 -> 2825096.3 | F4: =IFERROR(E4/C4,0) -> 0.13732086
A5: Актюбинская область | B5: =SUMIFS(Моделирование!$E$8:$E$219,Моделирование!$B$8:$B$219,$A5) -> 937248 | C5: =SUMIFS(Моделирование!$H$8:$H$219,Моделирование!$B$8:$B$219,$A5) -> 24051106 | D5: =SUMIFS(Моделирование!$I$8:$I$219,Моделирование!$B$8:$B$219,$A5) -> 25660665 | E5: =D5-C5 -> 1609558.3 | F5: =IFERROR(E5/C5,0) -> 0.06692242
A6: Алматинская область | B6: =SUMIFS(Моделирование!$E$8:$E$219,Моделирование!$B$8:$B$219,$A6) -> 1649754 | C6: =SUMIFS(Моделирование!$H$8:$H$219,Моделирование!$B$8:$B$219,$A6) -> 36455978 | D6: =SUMIFS(Моделирование!$I$8:$I$219,Моделирование!$B$8:$B$219,$A6) -> 40040581 | E6: =D6-C6 -> 3584602.9 | F6: =IFERROR(E6/C6,0) -> 0.098326887
A7: Атырауская область | B7: =SUMIFS(Моделирование!$E$8:$E$219,Моделирование!$B$8:$B$219,$A7) -> 707248 | C7: =SUMIFS(Моделирование!$H$8:$H$219,Моделирование!$B$8:$B$219,$A7) -> 18598476 | D7: =SUMIFS(Моделирование!$I$8:$I$219,Моделирование!$B$8:$B$219,$A7) -> 19391677 | E7: =D7-C7 -> 793200.95 | F7: =IFERROR(E7/C7,0) -> 0.042648707
A8: Восточно-Казахстанская область | B8: =SUMIFS(Моделирование!$E$8:$E$219,Моделирование!$B$8:$B$219,$A8) -> 710040 | C8: =SUMIFS(Моделирование!$H$8:$H$219,Моделирование!$B$8:$B$219,$A8) -> 18834782 | D8: =SUMIFS(Моделирование!$I$8:$I$219,Моделирование!$B$8:$B$219,$A8) -> 21018818 | E8: =D8-C8 -> 2184036.4 | F8: =IFERROR(E8/C8,0) -> 0.11595762
A9: Жамбылская область | B9: =SUMIFS(Моделирование!$E$8:$E$219,Моделирование!$B$8:$B$219,$A9) -> 1174485 | C9: =SUMIFS(Моделирование!$H$8:$H$219,Моделирование!$B$8:$B$219,$A9) -> 27152447 | D9: =SUMIFS(Моделирование!$I$8:$I$219,Моделирование!$B$8:$B$219,$A9) -> 30991796 | E9: =D9-C9 -> 3839348.5 | F9: =IFERROR(E9/C9,0) -> 0.14139972
A10: Западно-Казахстанская область | B10: =SUMIFS(Моделирование!$E$8:$E$219,Моделирование!$B$8:$B$219,$A10) -> 687556 | C10: =SUMIFS(Моделирование!$H$8:$H$219,Моделирование!$B$8:$B$219,$A10) -> 20353644 | D10: =SUMIFS(Моделирование!$I$8:$I$219,Моделирование!$B$8:$B$219,$A10) -> 22014578 | E10: =D10-C10 -> 1660933.2 | F10: =IFERROR(E10/C10,0) -> 0.081603725
A11: Карагандинская область | B11: =SUMIFS(Моделирование!$E$8:$E$219,Моделирование!$B$8:$B$219,$A11) -> 1181097 | C11: =SUMIFS(Моделирование!$H$8:$H$219,Моделирование!$B$8:$B$219,$A11) -> 31037890 | D11: =SUMIFS(Моделирование!$I$8:$I$219,Моделирование!$B$8:$B$219,$A11) -> 32058110 | E11: =D11-C11 -> 1020219.5 | F11: =IFERROR(E11/C11,0) -> 0.03287013
A12: Костанайская область | B12: =SUMIFS(Моделирование!$E$8:$E$219,Моделирование!$B$8:$B$219,$A12) -> 776501 | C12: =SUMIFS(Моделирование!$H$8:$H$219,Моделирование!$B$8:$B$219,$A12) -> 21145752 | D12: =SUMIFS(Моделирование!$I$8:$I$219,Моделирование!$B$8:$B$219,$A12) -> 23020386 | E12: =D12-C12 -> 1874633.6 | F12: =IFERROR(E12/C12,0) -> 0.088652963
A13: Кызылординская область | B13: =SUMIFS(Моделирование!$E$8:$E$219,Моделирование!$B$8:$B$219,$A13) -> 821538 | C13: =SUMIFS(Моделирование!$H$8:$H$219,Моделирование!$B$8:$B$219,$A13) -> 23707476 | D13: =SUMIFS(Моделирование!$I$8:$I$219,Моделирование!$B$8:$B$219,$A13) -> 24984153 | E13: =D13-C13 -> 1276676.6 | F13: =IFERROR(E13/C13,0) -> 0.053851222
A14: Мангистауская область | B14: =SUMIFS(Моделирование!$E$8:$E$219,Моделирование!$B$8:$B$219,$A14) -> 831774 | C14: =SUMIFS(Моделирование!$H$8:$H$219,Моделирование!$B$8:$B$219,$A14) -> 21385307 | D14: =SUMIFS(Моделирование!$I$8:$I$219,Моделирование!$B$8:$B$219,$A14) -> 22075873 | E14: =D14-C14 -> 690566.62 | F14: =IFERROR(E14/C14,0) -> 0.032291639
A15: Павлодарская область | B15: =SUMIFS(Моделирование!$E$8:$E$219,Моделирование!$B$8:$B$219,$A15) -> 745936 | C15: =SUMIFS(Моделирование!$H$8:$H$219,Моделирование!$B$8:$B$219,$A15) -> 21347799 | D15: =SUMIFS(Моделирование!$I$8:$I$219,Моделирование!$B$8:$B$219,$A15) -> 21967559 | E15: =D15-C15 -> 619760.42 | F15: =IFERROR(E15/C15,0) -> 0.029031584
... A23: г. Шымкент | B23: =SUMIFS(Моделирование!$E$8:$E$219,Моделирование!$B$8:$B$219,$A23) -> 1295884 | C23: =SUMIFS(Моделирование!$H$8:$H$219,Моделирование!$B$8:$B$219,$A23) -> 26220969 | D23: =SUMIFS(Моделирование!$I$8:$I$219,Моделирование!$B$8:$B$219,$A23) -> 26220969 | E23: =D23-C23 -> 0 | F23: =IFERROR(E23/C23,0) -> 0
A24: Итого по РК | B24: =SUM(B4:B23) -> 20477854 | C24: =SUM(C4:C23) -> 4.9814672e+08 | D24: =SUM(D4:D23) -> 5.2960553e+08 | E24: =SUM(E4:E23) -> 31458813 | F24: =IFERROR(E24/C24,0) -> 0.063151702
A26: Источники: численность – ЦС «РПН» на 01.08.2026 (выгрузка с КАТО от 04.10.2026); КПН 1 686,17 тенге и Кплотн действующий – приказ № ҚР ДСМ-170/2020 (ред. 31.12.2025), прил. 8 и прил. 5 к тарифам ПМСП;
A27: Кплотн по приказу № 309 – лист «Расчет Кплотн» (РПН на 01.01.2026, площадь МСХ на 01.01.2026, КАТО 18.09.2026). Другие поправочные коэффициенты не применяются.
A28: БКПН – по приказу № 170: 1 686,17 тенге, для субъектов районного значения и села 7 регионов – по приложению 1 к тарифам (1 850,91–2 249,81 тенге), лист «БКПН (приказ 170)».

Sheet Моделирование по МО
A1: Потребность на коэффициент плотности в разрезе субъектов ПМСП при КПН 1 686,17 тенге, тыс. тенге в год
A2: Расходы = Ч (РПН на 01.08.2026) × 12 × БКПН × Кплотн района МО / 1000; БКПН – лист «БКПН (приказ 170)», число месяцев – лист «Моделирование»
A4: № | B4: Регион (РПН) | C4: Наименование субъекта ПМСП | D4: Код района | E4: Район / город | F4: Прикреплённое население (РПН на 01.08.2026), чел. | G4: Кплотн по приказу № 170 | H4: Кплотн по приказу № 309 | I4: Расходы при Кплотн по приказу № 170 | J4: Расходы при Кплотн по приказу № 309 | K4: Потребность | L4: % | M4: БКПН, тенге (приказ № 170)
C5: Итого по РК | F5: =SUM(F6:F692) -> 20477854 | G5: =SUMPRODUCT(F6:F692,G6:G692)/F5 -> 1.1793069 | H5: =SUMPRODUCT(F6:F692,H6:H692)/F5 -> 1.2517542 | I5: =SUM(I6:I692) -> 4.9814672e+08 | J5: =SUM(J6:J692) -> 5.2960553e+08 | K5: =SUM(K6:K692) -> 31458813 | L5: =IFERROR(K5/I5,0) -> 0.063151702
A6: 1 | B6: ='РПН 01.08 по МО'!B4 -> АБАЙ | C6: ='РПН 01.08 по МО'!C4 -> "Коммунальное госудаственное предприятие на праве хозяйственного ведения "Аксуатская районная больница" управления здравоохранения области Абай" | D6: ='РПН 01.08 по МО'!E4 -> 1034 | E6: ='РПН 01.08 по МО'!F4 -> район Ақсуат | F6: ='РПН 01.08 по МО'!D4 -> 16574 | G6: =INDEX('Расчет Кплотн'!$K:$K,MATCH(D6,'Расчет Кплотн'!$A:$A,0)) -> 2 | H6: =INDEX('Расчет Кплотн'!$J:$J,MATCH(D6,'Расчет Кплотн'!$A:$A,0)) -> 2 | I6: =F6*Моделирование!$F$3*M6*G6/1000 -> 760511.91 | J6: =F6*Моделирование!$F$3*M6*H6/1000 -> 760511.91 | K6: =J6-I6 -> 0 | L6: =IFERROR(K6/I6,0) -> 0 | M6: =IF(INDEX('Расчет Кплотн'!$D:$D,MATCH(D6,'Расчет Кплотн'!$A:$A,0))="район",IFERROR(VLOOKUP(INDEX('Расчет Кплотн'!$B:$B,MATCH(D6,'Расчет Кплотн'!$A:$A,0)),'БКПН (приказ 170)'!$A$4:$C$10,3,FALSE()),Моделирование!$F$2),Моделирование!$F$2) -> 1911.91
A7: 2 | B7: ='РПН 01.08 по МО'!B5 -> АБАЙ | C7: ='РПН 01.08 по МО'!C5 -> Учреждение "Семейная амбулатория "Азат" | D7: ='РПН 01.08 по МО'!E5 -> 1042 | E7: ='РПН 01.08 по МО'!F5 -> Жарминский район | F7: ='РПН 01.08 по МО'!D5 -> 3039 | G7: =INDEX('Расчет Кплотн'!$K:$K,MATCH(D7,'Расчет Кплотн'!$A:$A,0)) -> 2 | H7: =INDEX('Расчет Кплотн'!$J:$J,MATCH(D7,'Расчет Кплотн'!$A:$A,0)) -> 2 | I7: =F7*Моделирование!$F$3*M7*G7/1000 -> 139447.07 | J7: =F7*Моделирование!$F$3*M7*H7/1000 -> 139447.07 | K7: =J7-I7 -> 0 | L7: =IFERROR(K7/I7,0) -> 0 | M7: =IF(INDEX('Расчет Кплотн'!$D:$D,MATCH(D7,'Расчет Кплотн'!$A:$A,0))="район",IFERROR(VLOOKUP(INDEX('Расчет Кплотн'!$B:$B,MATCH(D7,'Расчет Кплотн'!$A:$A,0)),'БКПН (приказ 170)'!$A$4:$C$10,3,FALSE()),Моделирование!$F$2),Моделирование!$F$2) -> 1911.91
A8: 3 | B8: ='РПН 01.08 по МО'!B6 -> АБАЙ | C8: ='РПН 01.08 по МО'!C6 -> У-е "Сельская амбулатория "Гармония" | D8: ='РПН 01.08 по МО'!E6 -> 1041 | E8: ='РПН 01.08 по МО'!F6 -> район Жаңасемей | F8: ='РПН 01.08 по МО'!D6 -> 1781 | G8: =INDEX('Расчет Кплотн'!$K:$K,MATCH(D8,'Расчет Кплотн'!$A:$A,0)) -> 1 | H8: =INDEX('Расчет Кплотн'!$J:$J,MATCH(D8,'Расчет Кплотн'!$A:$A,0)) -> 2 | I8: =F8*Моделирование!$F$3*M8*G8/1000 -> 40861.341 | J8: =F8*Моделирование!$F$3*M8*H8/1000 -> 81722.681 | K8: =J8-I8 -> 40861.341 | L8: =IFERROR(K8/I8,0) -> 1 | M8: =IF(INDEX('Расчет Кплотн'!$D:$D,MATCH(D8,'Расчет Кплотн'!$A:$A,0))="район",IFERROR(VLOOKUP(INDEX('Расчет Кплотн'!$B:$B,MATCH(D8,'Расчет Кплотн'!$A:$A,0)),'БКПН (приказ 170)'!$A$4:$C$10,3,FALSE()),Моделирование!$F$2),Моделирование!$F$2) -> 1911.91
A9: 4 | B9: ='РПН 01.08 по МО'!B7 -> АБАЙ | C9: ='РПН 01.08 по МО'!C7 -> У-е "Поликлиника "Хаким" | D9: ='РПН 01.08 по МО'!E7 -> 1010 | E9: ='РПН 01.08 по МО'!F7 -> Семей | F9: ='РПН 01.08 по МО'!D7 -> 11648 | G9: =INDEX('Расчет Кплотн'!$K:$K,MATCH(D9,'Расчет Кплотн'!$A:$A,0)) -> 1 | H9: =INDEX('Расчет Кплотн'!$J:$J,MATCH(D9,'Расчет Кплотн'!$A:$A,0)) -> 1 | I9: =F9*Моделирование!$F$3*M9*G9/1000 -> 235686.1 | J9: =F9*Моделирование!$F$3*M9*H9/1000 -> 235686.1 | K9: =J9-I9 -> 0 | L9: =IFERROR(K9/I9,0) -> 0 | M9: =IF(INDEX('Расчет Кплотн'!$D:$D,MATCH(D9,'Расчет Кплотн'!$A:$A,0))="район",IFERROR(VLOOKUP(INDEX('Расчет Кплотн'!$B:$B,MATCH(D9,'Расчет Кплотн'!$A:$A,0)),'БКПН (приказ 170)'!$A$4:$C$10,3,FALSE()),Моделирование!$F$2),Моделирование!$F$2) -> 1686.17
A10: 5 | B10: ='РПН 01.08 по МО'!B8 -> АБАЙ | C10: ='РПН 01.08 по МО'!C8 -> У-е "Консультативно-диагностическая поликлиника № 3 города Семей" | D10: ='РПН 01.08 по МО'!E8 -> 1010 | E10: ='РПН 01.08 по МО'!F8 -> Семей | F10: ='РПН 01.08 по МО'!D8 -> 19155 | G10: =INDEX('Расчет Кплотн'!$K:$K,MATCH(D10,'Расчет Кплотн'!$A:$A,0)) -> 1 | H10: =INDEX('Расчет Кплотн'!$J:$J,MATCH(D10,'Расчет Кплотн'!$A:$A,0)) -> 1 | I10: =F10*Моделирование!$F$3*M10*G10/1000 -> 387583.04 | J10: =F10*Моделирование!$F$3*M10*H10/1000 -> 387583.04 | K10: =J10-I10 -> 0 | L10: =IFERROR(K10/I10,0) -> 0 | M10: =IF(INDEX('Расчет Кплотн'!$D:$D,MATCH(D10,'Расчет Кплотн'!$A:$A,0))="район",IFERROR(VLOOKUP(INDEX('Расчет Кплотн'!$B:$B,MATCH(D10,'Расчет Кплотн'!$A:$A,0)),'БКПН (приказ 170)'!$A$4:$C$10,3,FALSE()),Моделирование!$F$2),Моделирование!$F$2) -> 1686.17
A11: 6 | B11: ='РПН 01.08 по МО'!B9 -> АБАЙ | C11: ='РПН 01.08 по МО'!C9 -> ТОО "Семейская железнодорожная больница" | D11: ='РПН 01.08 по МО'!E9 -> 1010 | E11: ='РПН 01.08 по МО'!F9 -> Семей | F11: ='РПН 01.08 по МО'!D9 -> 35438 | G11: =INDEX('Расчет Кплотн'!$K:$K,MATCH(D11,'Расчет Кплотн'!$A:$A,0)) -> 1 | H11: =INDEX('Расчет Кплотн'!$J:$J,MATCH(D11,'Расчет Кплотн'!$A:$A,0)) -> 1 | I11: =F11*Моделирование!$F$3*M11*G11/1000 -> 717053.91 | J11: =F11*Моделирование!$F$3*M11*H11/1000 -> 717053.91 | K11: =J11-I11 -> 0 | L11: =IFERROR(K11/I11,0) -> 0 | M11: =IF(INDEX('Расчет Кплотн'!$D:$D,MATCH(D11,'Расчет Кплотн'!$A:$A,0))="район",IFERROR(VLOOKUP(INDEX('Расчет Кплотн'!$B:$B,MATCH(D11,'Расчет Кплотн'!$A:$A,0)),'БКПН (приказ 170)'!$A$4:$C$10,3,FALSE()),Моделирование!$F$2),Моделирование!$F$2) -> 1686.17
A12: 7 | B12: ='РПН 01.08 по МО'!B10 -> АБАЙ | C12: ='РПН 01.08 по МО'!C10 -> ТОО "Поликлиника №6 города Семей" | D12: ='РПН 01.08 по МО'!E10 -> 1010 | E12: ='РПН 01.08 по МО'!F10 -> Семей | F12: ='РПН 01.08 по МО'!D10 -> 38899 | G12: =INDEX('Расчет Кплотн'!$K:$K,MATCH(D12,'Расчет Кплотн'!$A:$A,0)) -> 1 | H12: =INDEX('Расчет Кплотн'!$J:$J,MATCH(D12,'Расчет Кплотн'!$A:$A,0)) -> 1 | I12: =F12*Моделирование!$F$3*M12*G12/1000 -> 787083.92 | J12: =F12*Моделирование!$F$3*M12*H12/1000 -> 787083.92 | K12: =J12-I12 -> 0 | L12: =IFERROR(K12/I12,0) -> 0 | M12: =IF(INDEX('Расчет Кплотн'!$D:$D,MATCH(D12,'Расчет Кплотн'!$A:$A,0))="район",IFERROR(VLOOKUP(INDEX('Расчет Кплотн'!$B:$B,MATCH(D12,'Расчет Кплотн'!$A:$A,0)),'БКПН (приказ 170)'!$A$4:$C$10,3,FALSE()),Моделирование!$F$2),Моделирование!$F$2) -> 1686.17
A13: 8 | B13: ='РПН 01.08 по МО'!B11 -> АБАЙ | C13: ='РПН 01.08 по МО'!C11 -> ТОО "Клиника iv plus" | D13: ='РПН 01.08 по МО'!E11 -> 1010 | E13: ='РПН 01.08 по МО'!F11 -> Семей | F13: ='РПН 01.08 по МО'!D11 -> 6865 | G13: =INDEX('Расчет Кплотн'!$K:$K,MATCH(D13,'Расчет Кплотн'!$A:$A,0)) -> 1 | H13: =INDEX('Расчет Кплотн'!$J:$J,MATCH(D13,'Расчет Кплотн'!$A:$A,0)) -> 1 | I13: =F13*Моделирование!$F$3*M13*G13/1000 -> 138906.68 | J13: =F13*Моделирование!$F$3*M13*H13/1000 -> 138906.68 | K13: =J13-I13 -> 0 | L13: =IFERROR(K13/I13,0) -> 0 | M13: =IF(INDEX('Расчет Кплотн'!$D:$D,MATCH(D13,'Расчет Кплотн'!$A:$A,0))="район",IFERROR(VLOOKUP(INDEX('Расчет Кплотн'!$B:$B,MATCH(D13,'Расчет Кплотн'!$A:$A,0)),'БКПН (приказ 170)'!$A$4:$C$10,3,FALSE()),Моделирование!$F$2),Моделирование!$F$2) -> 1686.17
A14: 9 | B14: ='РПН 01.08 по МО'!B12 -> АБАЙ | C14: ='РПН 01.08 по МО'!C12 -> ТОО "Қазығұл" | D14: ='РПН 01.08 по МО'!E12 -> 1036 | E14: ='РПН 01.08 по МО'!F12 -> Аягозский район | F14: ='РПН 01.08 по МО'!D12 -> 12762 | G14: =INDEX('Расчет Кплотн'!$K:$K,MATCH(D14,'Расчет Кплотн'!$A:$A,0)) -> 2 | H14: =INDEX('Расчет Кплотн'!$J:$J,MATCH(D14,'Расчет Кплотн'!$A:$A,0)) -> 2 | I14: =F14*Моделирование!$F$3*M14*G14/1000 -> 585595.09 | J14: =F14*Моделирование!$F$3*M14*H14/1000 -> 585595.09 | K14: =J14-I14 -> 0 | L14: =IFERROR(K14/I14,0) -> 0 | M14: =IF(INDEX('Расчет Кплотн'!$D:$D,MATCH(D14,'Расчет Кплотн'!$A:$A,0))="район",IFERROR(VLOOKUP(INDEX('Расчет Кплотн'!$B:$B,MATCH(D14,'Расчет Кплотн'!$A:$A,0)),'БКПН (приказ 170)'!$A$4:$C$10,3,FALSE()),Моделирование!$F$2),Моделирование!$F$2) -> 1911.91
A15: 10 | B15: ='РПН 01.08 по МО'!B13 -> АБАЙ | C15: ='РПН 01.08 по МО'!C13 -> ТОО "Жан-Ер" | D15: ='РПН 01.08 по МО'!E13 -> 1010 | E15: ='РПН 01.08 по МО'!F13 -> Семей | F15: ='РПН 01.08 по МО'!D13 -> 9299 | G15: =INDEX('Расчет Кплотн'!$K:$K,MATCH(D15,'Расчет Кплотн'!$A:$A,0)) -> 1 | H15: =INDEX('Расчет Кплотн'!$J:$J,MATCH(D15,'Расчет Кплотн'!$A:$A,0)) -> 1 | I15: =F15*Моделирование!$F$3*M15*G15/1000 -> 188156.34 | J15: =F15*Моделирование!$F$3*M15*H15/1000 -> 188156.34 | K15: =J15-I15 -> 0 | L15: =IFERROR(K15/I15,0) -> 0 | M15: =IF(INDEX('Расчет Кплотн'!$D:$D,MATCH(D15,'Расчет Кплотн'!$A:$A,0))="район",IFERROR(VLOOKUP(INDEX('Расчет Кплотн'!$B:$B,MATCH(D15,'Расчет Кплотн'!$A:$A,0)),'БКПН (приказ 170)'!$A$4:$C$10,3,FALSE()),Моделирование!$F$2),Моделирование!$F$2) -> 1686.17
A16: 11 | B16: ='РПН 01.08 по МО'!B14 -> АБАЙ | C16: ='РПН 01.08 по МО'!C14 -> МУ "Центральная смотровая поликлиника" | D16: ='РПН 01.08 по МО'!E14 -> 1010 | E16: ='РПН 01.08 по МО'!F14 -> Семей | F16: ='РПН 01.08 по МО'!D14 -> 17291 | G16: =INDEX('Расчет Кплотн'!$K:$K,MATCH(D16,'Расчет Кплотн'!$A:$A,0)) -> 1 | H16: =INDEX('Расчет Кплотн'!$J:$J,MATCH(D16,'Расчет Кплотн'!$A:$A,0)) -> 1 | I16: =F16*Моделирование!$F$3*M16*G16/1000 -> 349866.79 | J16: =F16*Моделирование!$F$3*M16*H16/1000 -> 349866.79 | K16: =J16-I16 -> 0 | L16: =IFERROR(K16/I16,0) -> 0 | M16: =IF(INDEX('Расчет Кплотн'!$D:$D,MATCH(D16,'Расчет Кплотн'!$A:$A,0))="район",IFERROR(VLOOKUP(INDEX('Расчет Кплотн'!$B:$B,MATCH(D16,'Расчет Кплотн'!$A:$A,0)),'БКПН (приказ 170)'!$A$4:$C$10,3,FALSE()),Моделирование!$F$2),Моделирование!$F$2) -> 1686.17
A17: 12 | B17: ='РПН 01.08 по МО'!B15 -> АБАЙ | C17: ='РПН 01.08 по МО'!C15 -> Медицинское учреждение "Поликлиника № 8 города Семей" | D17: ='РПН 01.08 по МО'!E15 -> 1010 | E17: ='РПН 01.08 по МО'!F15 -> Семей | F17: ='РПН 01.08 по МО'!D15 -> 9013 | G17: =INDEX('Расчет Кплотн'!$K:$K,MATCH(D17,'Расчет Кплотн'!$A:$A,0)) -> 1 | H17: =INDEX('Расчет Кплотн'!$J:$J,MATCH(D17,'Расчет Кплотн'!$A:$A,0)) -> 1 | I17: =F17*Моделирование!$F$3*M17*G17/1000 -> 182369.4 | J17: =F17*Моделирование!$F$3*M17*H17/1000 -> 182369.4 | K17: =J17-I17 -> 0 | L17: =IFERROR(K17/I17,0) -> 0 | M17: =IF(INDEX('Расчет Кплотн'!$D:$D,MATCH(D17,'Расчет Кплотн'!$A:$A,0))="район",IFERROR(VLOOKUP(INDEX('Расчет Кплотн'!$B:$B,MATCH(D17,'Расчет Кплотн'!$A:$A,0)),'БКПН (приказ 170)'!$A$4:$C$10,3,FALSE()),Моделирование!$F$2),Моделирование!$F$2) -> 1686.17
... A692: 687 | B692: ='РПН 01.08 по МО'!B690 -> ШЫМКЕНТ | C692: ='РПН 01.08 по МО'!C690 -> Частное учреждение "Семейно-врачебная амбулатория Интертич города Шымкент" | D692: ='РПН 01.08 по МО'!E690 -> 7900 | E692: ='РПН 01.08 по МО'!F690 -> г. Шымкент | F692: ='РПН 01.08 по МО'!D690 -> 3397 | G692: =INDEX('Расчет Кплотн'!$K:$K,MATCH(D692,'Расчет Кплотн'!$A:$A,0)) -> 1 | H692: =INDEX('Расчет Кплотн'!$J:$J,MATCH(D692,'Расчет Кплотн'!$A:$A,0)) -> 1 | I692: =F692*Моделирование!$F$3*M692*G692/1000 -> 68735.034 | J692: =F692*Моделирование!$F$3*M692*H692/1000 -> 68735.034 | K692: =J692-I692 -> 0 | L692: =IFERROR(K692/I692,0) -> 0 | M692: =IF(INDEX('Расчет Кплотн'!$D:$D,MATCH(D692,'Расчет Кплотн'!$A:$A,0))="район",IFERROR(VLOOKUP(INDEX('Расчет Кплотн'!$B:$B,MATCH(D692,'Расчет Кплотн'!$A:$A,0)),'БКПН (приказ 170)'!$A$4:$C$10,3,FALSE()),Моделирование!$F$2),Моделирование!$F$2) -> 1686.17
A694: Субъекты с ростом финансирования: | E694: =COUNTIF(K6:K692,">0.5") -> 182
A695: Субъекты без изменений: | E695: =COUNTIF(K6:K692,"<=0.5")-COUNTIF(K6:K692,"<-0.5") -> 505
A696: Субъекты со снижением: | E696: =COUNTIF(K6:K692,"<-0.5") -> 0

Sheet Моделирование
A1: Потребность на коэффициент плотности населения для ПМСП при действующем КПН (приказ № 170), тыс. тенге в год
A2: Действующий базовый КПН ПМСП, тенге на 1 прикреплённого в месяц | F2: 1686.17
A3: Количество месяцев | F3: 12
A4: Расходы = Ч (РПН на 01.08.2026) × 12 × БКПН × Кплотн / 1000; БКПН – по приказу № 170 с учётом приложения 1 (районное значение и село в 7 регионах); другие поправочные коэффициенты не применяются
A6: Код района | B6: Регион | C6: Район / город | D6: Тип территории | E6: Прикреплённое население (РПН на 01.08.2026), чел. | F6: Кплотн по приказу № 170 | G6: Кплотн по приказу № 309 | H6: Расходы при Кплотн по приказу № 170 | I6: Расходы при Кплотн по приказу № 309 | J6: Потребность | K6: % | L6: БКПН, тенге (приказ № 170)
C7: Итого по РК | E7: =SUM(E8:E219) -> 20477854 | F7: =SUMPRODUCT(E8:E219,F8:F219)/E7 -> 1.1793069 | G7: =SUMPRODUCT(E8:E219,G8:G219)/E7 -> 1.2517542 | H7: =SUM(H8:H219) -> 4.9814672e+08 | I7: =SUM(I8:I219) -> 5.2960553e+08 | J7: =SUM(J8:J219) -> 31458813 | K7: =IFERROR(J7/H7,0) -> 0.063151702
A8: 1010 | B8: область Абай | C8: ='Расчет Кплотн'!C8 -> Семей | D8: ='Расчет Кплотн'!D8 -> областной центр | E8: =SUMIFS('РПН 01.08 по МО'!$D:$D,'РПН 01.08 по МО'!$E:$E,A8) -> 362985 | F8: ='Расчет Кплотн'!K8 -> 1 | G8: ='Расчет Кплотн'!J8 -> 1 | H8: =E8*$F$3*L8*F8/1000 -> 7344653 | I8: =E8*$F$3*L8*G8/1000 -> 7344653 | J8: =I8-H8 -> 0 | K8: =IFERROR(J8/H8,0) -> 0 | L8: =IF(D8="район",IFERROR(VLOOKUP(B8,'БКПН (приказ 170)'!$A$4:$C$10,3,FALSE()),$F$2),$F$2) -> 1686.17
A9: 1018 | B9: область Абай | C9: ='Расчет Кплотн'!C9 -> Курчатов | D9: ='Расчет Кплотн'!D9 -> моногород / малый город | E9: =SUMIFS('РПН 01.08 по МО'!$D:$D,'РПН 01.08 по МО'!$E:$E,A9) -> 9897 | F9: ='Расчет Кплотн'!K9 -> 1.5 | G9: ='Расчет Кплотн'!J9 -> 1.5 | H9: =E9*$F$3*L9*F9/1000 -> 300384.44 | I9: =E9*$F$3*L9*G9/1000 -> 300384.44 | J9: =I9-H9 -> 0 | K9: =IFERROR(J9/H9,0) -> 0 | L9: =IF(D9="район",IFERROR(VLOOKUP(B9,'БКПН (приказ 170)'!$A$4:$C$10,3,FALSE()),$F$2),$F$2) -> 1686.17
A10: 1032 | B10: область Абай | C10: ='Расчет Кплотн'!C10 -> Абайский район | D10: ='Расчет Кплотн'!D10 -> район | E10: =SUMIFS('РПН 01.08 по МО'!$D:$D,'РПН 01.08 по МО'!$E:$E,A10) -> 10794 | F10: ='Расчет Кплотн'!K10 -> 2 | G10: ='Расчет Кплотн'!J10 -> 2 | H10: =E10*$F$3*L10*F10/1000 -> 495291.76 | I10: =E10*$F$3*L10*G10/1000 -> 495291.76 | J10: =I10-H10 -> 0 | K10: =IFERROR(J10/H10,0) -> 0 | L10: =IF(D10="район",IFERROR(VLOOKUP(B10,'БКПН (приказ 170)'!$A$4:$C$10,3,FALSE()),$F$2),$F$2) -> 1911.91
A11: 1034 | B11: область Абай | C11: ='Расчет Кплотн'!C11 -> район Ақсуат | D11: ='Расчет Кплотн'!D11 -> район | E11: =SUMIFS('РПН 01.08 по МО'!$D:$D,'РПН 01.08 по МО'!$E:$E,A11) -> 16574 | F11: ='Расчет Кплотн'!K11 -> 2 | G11: ='Расчет Кплотн'!J11 -> 2 | H11: =E11*$F$3*L11*F11/1000 -> 760511.91 | I11: =E11*$F$3*L11*G11/1000 -> 760511.91 | J11: =I11-H11 -> 0 | K11: =IFERROR(J11/H11,0) -> 0 | L11: =IF(D11="район",IFERROR(VLOOKUP(B11,'БКПН (приказ 170)'!$A$4:$C$10,3,FALSE()),$F$2),$F$2) -> 1911.91
A12: 1036 | B12: область Абай | C12: ='Расчет Кплотн'!C12 -> Аягозский район | D12: ='Расчет Кплотн'!D12 -> район | E12: =SUMIFS('РПН 01.08 по МО'!$D:$D,'РПН 01.08 по МО'!$E:$E,A12) -> 60975 | F12: ='Расчет Кплотн'!K12 -> 2 | G12: ='Расчет Кплотн'!J12 -> 2 | H12: =E12*$F$3*L12*F12/1000 -> 2797889.1 | I12: =E12*$F$3*L12*G12/1000 -> 2797889.1 | J12: =I12-H12 -> 0 | K12: =IFERROR(J12/H12,0) -> 0 | L12: =IF(D12="район",IFERROR(VLOOKUP(B12,'БКПН (приказ 170)'!$A$4:$C$10,3,FALSE()),$F$2),$F$2) -> 1911.91
A13: 1038 | B13: область Абай | C13: ='Расчет Кплотн'!C13 -> Бескарагайский район | D13: ='Расчет Кплотн'!D13 -> район | E13: =SUMIFS('РПН 01.08 по МО'!$D:$D,'РПН 01.08 по МО'!$E:$E,A13) -> 13938 | F13: ='Расчет Кплотн'!K13 -> 2 | G13: ='Расчет Кплотн'!J13 -> 2 | H13: =E13*$F$3*L13*F13/1000 -> 639556.84 | I13: =E13*$F$3*L13*G13/1000 -> 639556.84 | J13: =I13-H13 -> 0 | K13: =IFERROR(J13/H13,0) -> 0 | L13: =IF(D13="район",IFERROR(VLOOKUP(B13,'БКПН (приказ 170)'!$A$4:$C$10,3,FALSE()),$F$2),$F$2) -> 1911.91
A14: 1040 | B14: область Абай | C14: ='Расчет Кплотн'!C14 -> Бородулихинский район | D14: ='Расчет Кплотн'!D14 -> район | E14: =SUMIFS('РПН 01.08 по МО'!$D:$D,'РПН 01.08 по МО'!$E:$E,A14) -> 28085 | F14: ='Расчет Кплотн'!K14 -> 1.4339 | G14: ='Расчет Кплотн'!J14 -> 2 | H14: =E14*$F$3*L14*F14/1000 -> 923936.2 | I14: =E14*$F$3*L14*G14/1000 -> 1288703.8 | J14: =I14-H14 -> 364767.62 | K14: =IFERROR(J14/H14,0) -> 0.39479741 | L14: =IF(D14="район",IFERROR(VLOOKUP(B14,'БКПН (приказ 170)'!$A$4:$C$10,3,FALSE()),$F$2),$F$2) -> 1911.91
A15: 1041 | B15: область Абай | C15: ='Расчет Кплотн'!C15 -> район Жаңасемей | D15: ='Расчет Кплотн'!D15 -> район | E15: =SUMIFS('РПН 01.08 по МО'!$D:$D,'РПН 01.08 по МО'!$E:$E,A15) -> 6327 | F15: ='Расчет Кплотн'!K15 -> 1 | G15: ='Расчет Кплотн'!J15 -> 2 | H15: =E15*$F$3*L15*F15/1000 -> 145159.85 | I15: =E15*$F$3*L15*G15/1000 -> 290319.71 | J15: =I15-H15 -> 145159.85 | K15: =IFERROR(J15/H15,0) -> 1 | L15: =IF(D15="район",IFERROR(VLOOKUP(B15,'БКПН (приказ 170)'!$A$4:$C$10,3,FALSE()),$F$2),$F$2) -> 1911.91
A16: 1042 | B16: область Абай | C16: ='Расчет Кплотн'!C16 -> Жарминский район | D16: ='Расчет Кплотн'!D16 -> район | E16: =SUMIFS('РПН 01.08 по МО'!$D:$D,'РПН 01.08 по МО'!$E:$E,A16) -> 31813 | F16: ='Расчет Кплотн'!K16 -> 2 | G16: ='Расчет Кплотн'!J16 -> 2 | H16: =E16*$F$3*L16*F16/1000 -> 1459766.2 | I16: =E16*$F$3*L16*G16/1000 -> 1459766.2 | J16: =I16-H16 -> 0 | K16: =IFERROR(J16/H16,0) -> 0 | L16: =IF(D16="район",IFERROR(VLOOKUP(B16,'БКПН (приказ 170)'!$A$4:$C$10,3,FALSE()),$F$2),$F$2) -> 1911.91
A17: 1044 | B17: область Абай | C17: ='Расчет Кплотн'!C17 -> Кокпектинский район | D17: ='Расчет Кплотн'!D17 -> район | E17: =SUMIFS('РПН 01.08 по МО'!$D:$D,'РПН 01.08 по МО'!$E:$E,A17) -> 11539 | F17: ='Расчет Кплотн'!K17 -> 2 | G17: ='Расчет Кплотн'!J17 -> 2 | H17: =E17*$F$3*L17*F17/1000 -> 529476.71 | I17: =E17*$F$3*L17*G17/1000 -> 529476.71 | J17: =I17-H17 -> 0 | K17: =IFERROR(J17/H17,0) -> 0 | L17: =IF(D17="район",IFERROR(VLOOKUP(B17,'БКПН (приказ 170)'!$A$4:$C$10,3,FALSE()),$F$2),$F$2) -> 1911.91
A18: 1045 | B18: область Абай | C18: ='Расчет Кплотн'!C18 -> район Мақаншы | D18: ='Расчет Кплотн'!D18 -> район | E18: =SUMIFS('РПН 01.08 по МО'!$D:$D,'РПН 01.08 по МО'!$E:$E,A18) -> 22985 | F18: ='Расчет Кплотн'!K18 -> 1.6934 | G18: ='Расчет Кплотн'!J18 -> 2 | H18: =E18*$F$3*L18*F18/1000 -> 893002.66 | I18: =E18*$F$3*L18*G18/1000 -> 1054686 | J18: =I18-H18 -> 161683.37 | K18: =IFERROR(J18/H18,0) -> 0.18105586 | L18: =IF(D18="район",IFERROR(VLOOKUP(B18,'БКПН (приказ 170)'!$A$4:$C$10,3,FALSE()),$F$2),$F$2) -> 1911.91
A19: 1046 | B19: область Абай | C19: ='Расчет Кплотн'!C19 -> Урджарский район | D19: ='Расчет Кплотн'!D19 -> район | E19: =SUMIFS('РПН 01.08 по МО'!$D:$D,'РПН 01.08 по МО'!$E:$E,A19) -> 34454 | F19: ='Расчет Кплотн'!K19 -> 1.6934 | G19: ='Расчет Кплотн'!J19 -> 2 | H19: =E19*$F$3*L19*F19/1000 -> 1338591 | I19: =E19*$F$3*L19*G19/1000 -> 1580950.7 | J19: =I19-H19 -> 242359.75 | K19: =IFERROR(J19/H19,0) -> 0.18105586 | L19: =IF(D19="район",IFERROR(VLOOKUP(B19,'БКПН (приказ 170)'!$A$4:$C$10,3,FALSE()),$F$2),$F$2) -> 1911.91
... A208: 6348 | B208: Восточно-Казахстанская область | C208: ='Расчет Кплотн'!C208 -> район Алтай | D208: ='Расчет Кплотн'!D208 -> район | E208: =SUMIFS('РПН 01.08 по МО'!$D:$D,'РПН 01.08 по МО'!$E:$E,A208) -> 56419 | F208: ='Расчет Кплотн'!K208 -> 1.3549 | G208: ='Расчет Кплотн'!J208 -> 1.9417 | H208: =E208*$F$3*L208*F208/1000 -> 1753805.1 | I208: =E208*$F$3*L208*G208/1000 -> 2513368.7 | J208: =I208-H208 -> 759563.66 | K208: =IFERROR(J208/H208,0) -> 0.43309469 | L208: =IF(D208="район",IFERROR(VLOOKUP(B208,'БКПН (приказ 170)'!$A$4:$C$10,3,FALSE()),$F$2),$F$2) -> 1911.91
A209: 6352 | B209: Восточно-Казахстанская область | C209: ='Расчет Кплотн'!C209 -> Курчумский район | D209: ='Расчет Кплотн'!D209 -> район | E209: =SUMIFS('РПН 01.08 по МО'!$D:$D,'РПН 01.08 по МО'!$E:$E,A209)-E211 -> 13343 | F209: ='Расчет Кплотн'!K209 -> 2 | G209: ='Расчет Кплотн'!J209 -> 2 | H209: =E209*$F$3*L209*F209/1000 -> 612254.76 | I209: =E209*$F$3*L209*G209/1000 -> 612254.76 | J209: =I209-H209 -> 0 | K209: =IFERROR(J209/H209,0) -> 0 | L209: =IF(D209="район",IFERROR(VLOOKUP(B209,'БКПН (приказ 170)'!$A$4:$C$10,3,FALSE()),$F$2),$F$2) -> 1911.91
A210: 6354 | B210: Восточно-Казахстанская область | C210: ='Расчет Кплотн'!C210 -> Катон-Карагайский район | D210: ='Расчет Кплотн'!D210 -> район | E210: =SUMIFS('РПН 01.08 по МО'!$D:$D,'РПН 01.08 по МО'!$E:$E,A210) -> 8541 | F210: ='Расчет Кплотн'!K210 -> 2 | G210: ='Расчет Кплотн'!J210 -> 2 | H210: =E210*$F$3*L210*F210/1000 -> 391910.96 | I210: =E210*$F$3*L210*G210/1000 -> 391910.96 | J210: =I210-H210 -> 0 | K210: =IFERROR(J210/H210,0) -> 0 | L210: =IF(D210="район",IFERROR(VLOOKUP(B210,'БКПН (приказ 170)'!$A$4:$C$10,3,FALSE()),$F$2),$F$2) -> 1911.91
A211: 6355 | B211: Восточно-Казахстанская область | C211: ='Расчет Кплотн'!C211 -> район Марқакөл | D211: ='Расчет Кплотн'!D211 -> район | E211: ='Расчет Кплотн'!G211 -> 6285 | F211: ='Расчет Кплотн'!K211 -> 2 | G211: ='Расчет Кплотн'!J211 -> 2 | H211: =E211*$F$3*L211*F211/1000 -> 288392.5 | I211: =E211*$F$3*L211*G211/1000 -> 288392.5 | J211: =I211-H211 -> 0 | K211: =IFERROR(J211/H211,0) -> 0 | L211: =IF(D211="район",IFERROR(VLOOKUP(B211,'БКПН (приказ 170)'!$A$4:$C$10,3,FALSE()),$F$2),$F$2) -> 1911.91
A212: 6356 | B212: Восточно-Казахстанская область | C212: ='Расчет Кплотн'!C212 -> район Самар | D212: ='Расчет Кплотн'!D212 -> район | E212: =SUMIFS('РПН 01.08 по МО'!$D:$D,'РПН 01.08 по МО'!$E:$E,A212) -> 10576 | F212: ='Расчет Кплотн'!K212 -> 1.9345 | G212: ='Расчет Кплотн'!J212 -> 2 | H212: =E212*$F$3*L212*F212/1000 -> 469395.44 | I212: =E212*$F$3*L212*G212/1000 -> 485288.64 | J212: =I212-H212 -> 15893.203 | K212: =IFERROR(J212/H212,0) -> 0.033858878 | L212: =IF(D212="район",IFERROR(VLOOKUP(B212,'БКПН (приказ 170)'!$A$4:$C$10,3,FALSE()),$F$2),$F$2) -> 1911.91
A213: 6358 | B213: Восточно-Казахстанская область | C213: ='Расчет Кплотн'!C213 -> Тарбагатайский район | D213: ='Расчет Кплотн'!D213 -> район | E213: =SUMIFS('РПН 01.08 по МО'!$D:$D,'РПН 01.08 по МО'!$E:$E,A213) -> 16838 | F213: ='Расчет Кплотн'!K213 -> 2 | G213: ='Расчет Кплотн'!J213 -> 2 | H213: =E213*$F$3*L213*F213/1000 -> 772625.77 | I213: =E213*$F$3*L213*G213/1000 -> 772625.77 | J213: =I213-H213 -> 0 | K213: =IFERROR(J213/H213,0) -> 0 | L213: =IF(D213="район",IFERROR(VLOOKUP(B213,'БКПН (приказ 170)'!$A$4:$C$10,3,FALSE()),$F$2),$F$2) -> 1911.91
A214: 6362 | B214: Восточно-Казахстанская область | C214: ='Расчет Кплотн'!C214 -> Уланский район | D214: ='Расчет Кплотн'!D214 -> район | E214: =SUMIFS('РПН 01.08 по МО'!$D:$D,'РПН 01.08 по МО'!$E:$E,A214) -> 28068 | F214: ='Расчет Кплотн'!K214 -> 1.5835 | G214: ='Расчет Кплотн'!J214 -> 2 | H214: =E214*$F$3*L214*F214/1000 -> 1019713.6 | I214: =E214*$F$3*L214*G214/1000 -> 1287923.8 | J214: =I214-H214 -> 268210.12 | K214: =IFERROR(J214/H214,0) -> 0.26302494 | L214: =IF(D214="район",IFERROR(VLOOKUP(B214,'БКПН (приказ 170)'!$A$4:$C$10,3,FALSE()),$F$2),$F$2) -> 1911.91
A215: 6363 | B215: Восточно-Казахстанская область | C215: ='Расчет Кплотн'!C215 -> район Үлкен Нарын | D215: ='Расчет Кплотн'!D215 -> район | E215: =SUMIFS('РПН 01.08 по МО'!$D:$D,'РПН 01.08 по МО'!$E:$E,A215) -> 9397 | F215: ='Расчет Кплотн'!K215 -> 2 | G215: ='Расчет Кплотн'!J215 -> 2 | H215: =E215*$F$3*L215*F215/1000 -> 431189.24 | I215: =E215*$F$3*L215*G215/1000 -> 431189.24 | J215: =I215-H215 -> 0 | K215: =IFERROR(J215/H215,0) -> 0 | L215: =IF(D215="район",IFERROR(VLOOKUP(B215,'БКПН (приказ 170)'!$A$4:$C$10,3,FALSE()),$F$2),$F$2) -> 1911.91
A216: 6368 | B216: Восточно-Казахстанская область | C216: ='Расчет Кплотн'!C216 -> Шемонаихинский район | D216: ='Расчет Кплотн'!D216 -> район | E216: =SUMIFS('РПН 01.08 по МО'!$D:$D,'РПН 01.08 по МО'!$E:$E,A216) -> 39767 | F216: ='Расчет Кплотн'!K216 -> 1.1942 | G216: ='Расчет Кплотн'!J216 -> 1.5016 | H216: =E216*$F$3*L216*F216/1000 -> 1089553.6 | I216: =E216*$F$3*L216*G216/1000 -> 1370016.4 | J216: =I216-H216 -> 280462.88 | K216: =IFERROR(J216/H216,0) -> 0.25741082 | L216: =IF(D216="район",IFERROR(VLOOKUP(B216,'БКПН (приказ 170)'!$A$4:$C$10,3,FALSE()),$F$2),$F$2) -> 1911.91
A217: 7100 | B217: г. Астана | C217: ='Расчет Кплотн'!C217 -> г. Астана | D217: ='Расчет Кплотн'!D217 -> город респ. значения | E217: =SUMIFS('РПН 01.08 по МО'!$D:$D,'РПН 01.08 по МО'!$E:$E,A217) -> 1700015 | F217: ='Расчет Кплотн'!K217 -> 1 | G217: ='Расчет Кплотн'!J217 -> 1 | H217: =E217*$F$3*L217*F217/1000 -> 34398172 | I217: =E217*$F$3*L217*G217/1000 -> 34398172 | J217: =I217-H217 -> 0 | K217: =IFERROR(J217/H217,0) -> 0 | L217: =IF(D217="район",IFERROR(VLOOKUP(B217,'БКПН (приказ 170)'!$A$4:$C$10,3,FALSE()),$F$2),$F$2) -> 1686.17
A218: 7500 | B218: г. Алматы | C218: ='Расчет Кплотн'!C218 -> г. Алматы | D218: ='Расчет Кплотн'!D218 -> город респ. значения | E218: =SUMIFS('РПН 01.08 по МО'!$D:$D,'РПН 01.08 по МО'!$E:$E,A218) -> 2398435 | F218: ='Расчет Кплотн'!K218 -> 1 | G218: ='Расчет Кплотн'!J218 -> 1 | H218: =E218*$F$3*L218*F218/1000 -> 48530030 | I218: =E218*$F$3*L218*G218/1000 -> 48530030 | J218: =I218-H218 -> 0 | K218: =IFERROR(J218/H218,0) -> 0 | L218: =IF(D218="район",IFERROR(VLOOKUP(B218,'БКПН (приказ 170)'!$A$4:$C$10,3,FALSE()),$F$2),$F$2) -> 1686.17
A219: 7900 | B219: г. Шымкент | C219: ='Расчет Кплотн'!C219 -> г. Шымкент | D219: ='Расчет Кплотн'!D219 -> город респ. значения | E219: =SUMIFS('РПН 01.08 по МО'!$D:$D,'РПН 01.08 по МО'!$E:$E,A219) -> 1295884 | F219: ='Расчет Кплотн'!K219 -> 1 | G219: ='Расчет Кплотн'!J219 -> 1 | H219: =E219*$F$3*L219*F219/1000 -> 26220969 | I219: =E219*$F$3*L219*G219/1000 -> 26220969 | J219: =I219-H219 -> 0 | K219: =IFERROR(J219/H219,0) -> 0 | L219: =IF(D219="район",IFERROR(VLOOKUP(B219,'БКПН (приказ 170)'!$A$4:$C$10,3,FALSE()),$F$2),$F$2) -> 1686.17

Sheet Расчет Кплотн
A1: Коэффициент плотности населения для ПМСП по приказу № ҚР ДСМ-309/2020: Кплотн.район = 1 + В × Плотн.РК / Пнас.район
A2: Численность – ЦС «РПН» на 01.01.2026; район МО – по КАТО (18.09.2026); площадь – МСХ РК на 01.01.2026; сравнение – приказ № ҚР ДСМ-170/2020 (ред. 31.12.2025), прил. 5 к тарифам ПМСП.
A3: В (коэффициент корреляции Пирсона плотности и численности): | I3: =ROUND(CORREL(M8:M219,N8:N219),4) -> 0.689
A4: Плотн.РК, чел./км²: | I4: =H7 -> 7.444176
A6: Код района (КАТО) | B6: Регион | C6: Район / город | D6: Тип территории | E6: Площадь, тыс. га (МСХ) | F6: Площадь, км² | G6: Численность РПН на 01.01.2026, чел. | H6: Плотность, чел./км² | I6: Кплотн расчётный | J6: Кплотн по приказу № 309 | K6: Кплотн по приказу № 170 | L6: Изменение | M6: Для расчёта В: плотность (без городов респ. значения) | N6: Для расчёта В: численность (без городов респ. значения)
C7: Итого по РК | E7: =SUM(E8:E219) -> 272496.5 | F7: =SUM(F8:F219) -> 2724965 | G7: =SUM(G8:G219) -> 20285119 | H7: =G7/F7 -> 7.444176 | J7: =SUMPRODUCT(G8:G219,J8:J219)/G7 -> 1.2515183 | K7: =SUMPRODUCT(G8:G219,K8:K219)/G7 -> 1.178369 | L7: =J7-K7 -> 0.073149235
A8: 1010 | B8: область Абай | C8: Семей | D8: областной центр | E8: =SUMIFS('Площадь МСХ'!$D:$D,'Площадь МСХ'!$E:$E,A8) -> 29.8213 | F8: =E8*10 -> 298.213 | G8: =SUMIFS('РПН по МО'!$E:$E,'РПН по МО'!$F:$F,A8) -> 366217 | H8: =IF(G8>0,G8/F8,"") -> 1228.0383 | I8: =IF(G8>0,ROUND(1+$I$3*$I$4/H8,4),"") -> 1.0042 | J8: =IF(D8="район",MIN(I8,2),IF(D8="город респ. значения",1,IF(D8="областной центр",1,1.5))) -> 1 | K8: 1 | L8: =J8-K8 -> 0 | M8: =IF(D8="город респ. значения","",H8) -> 1228.0383 | N8: =IF(D8="город респ. значения","",G8) -> 366217
A9: 1018 | B9: область Абай | C9: Курчатов | D9: моногород / малый город | E9: =SUMIFS('Площадь МСХ'!$D:$D,'Площадь МСХ'!$E:$E,A9) -> 11.000003 | F9: =E9*10 -> 110.00003 | G9: =SUMIFS('РПН по МО'!$E:$E,'РПН по МО'!$F:$F,A9) -> 9984 | H9: =IF(G9>0,G9/F9,"") -> 90.763609 | I9: =IF(G9>0,ROUND(1+$I$3*$I$4/H9,4),"") -> 1.0565 | J9: =IF(D9="район",MIN(I9,2),IF(D9="город респ. значения",1,IF(D9="областной центр",1,1.5))) -> 1.5 | K9: 1.5 | L9: =J9-K9 -> 0 | M9: =IF(D9="город респ. значения","",H9) -> 90.763609 | N9: =IF(D9="город респ. значения","",G9) -> 9984
A10: 1032 | B10: область Абай | C10: Абайский район | D10: район | E10: =SUMIFS('Площадь МСХ'!$D:$D,'Площадь МСХ'!$E:$E,A10) -> 2009.391 | F10: =E10*10 -> 20093.91 | G10: =SUMIFS('РПН по МО'!$E:$E,'РПН по МО'!$F:$F,A10) -> 10869 | H10: =IF(G10>0,G10/F10,"") -> 0.54091016 | I10: =IF(G10>0,ROUND(1+$I$3*$I$4/H10,4),"") -> 10.4822 | J10: =IF(D10="район",MIN(I10,2),IF(D10="город респ. значения",1,IF(D10="областной центр",1,1.5))) -> 2 | K10: 2 | L10: =J10-K10 -> 0 | M10: =IF(D10="город респ. значения","",H10) -> 0.54091016 | N10: =IF(D10="город респ. значения","",G10) -> 10869
A11: 1034 | B11: область Абай | C11: район Ақсуат | D11: район | E11: =SUMIFS('Площадь МСХ'!$D:$D,'Площадь МСХ'!$E:$E,A11) -> 1356.19 | F11: =E11*10 -> 13561.9 | G11: =SUMIFS('РПН по МО'!$E:$E,'РПН по МО'!$F:$F,A11) -> 16638 | H11: =IF(G11>0,G11/F11,"") -> 1.2268193 | I11: =IF(G11>0,ROUND(1+$I$3*$I$4/H11,4),"") -> 5.1808 | J11: =IF(D11="район",MIN(I11,2),IF(D11="город респ. значения",1,IF(D11="областной центр",1,1.5))) -> 2 | K11: 2 | L11: =J11-K11 -> 0 | M11: =IF(D11="город респ. значения","",H11) -> 1.2268193 | N11: =IF(D11="город респ. значения","",G11) -> 16638
A12: 1036 | B12: область Абай | C12: Аягозский район | D12: район | E12: =SUMIFS('Площадь МСХ'!$D:$D,'Площадь МСХ'!$E:$E,A12) -> 4958.803 | F12: =E12*10 -> 49588.03 | G12: =SUMIFS('РПН по МО'!$E:$E,'РПН по МО'!$F:$F,A12) -> 60929 | H12: =IF(G12>0,G12/F12,"") -> 1.2287038 | I12: =IF(G12>0,ROUND(1+$I$3*$I$4/H12,4),"") -> 5.1743 | J12: =IF(D12="район",MIN(I12,2),IF(D12="город респ. значения",1,IF(D12="областной центр",1,1.5))) -> 2 | K12: 2 | L12: =J12-K12 -> 0 | M12: =IF(D12="город респ. значения","",H12) -> 1.2287038 | N12: =IF(D12="город респ. значения","",G12) -> 60929
A13: 1038 | B13: область Абай | C13: Бескарагайский район | D13: район | E13: =SUMIFS('Площадь МСХ'!$D:$D,'Площадь МСХ'!$E:$E,A13) -> 1137.3767 | F13: =E13*10 -> 11373.767 | G13: =SUMIFS('РПН по МО'!$E:$E,'РПН по МО'!$F:$F,A13) -> 14632 | H13: =IF(G13>0,G13/F13,"") -> 1.2864691 | I13: =IF(G13>0,ROUND(1+$I$3*$I$4/H13,4),"") -> 4.9869 | J13: =IF(D13="район",MIN(I13,2),IF(D13="город респ. значения",1,IF(D13="областной центр",1,1.5))) -> 2 | K13: 2 | L13: =J13-K13 -> 0 | M13: =IF(D13="город респ. значения","",H13) -> 1.2864691 | N13: =IF(D13="город респ. значения","",G13) -> 14632
A14: 1040 | B14: область Абай | C14: Бородулихинский район | D14: район | E14: =SUMIFS('Площадь МСХ'!$D:$D,'Площадь МСХ'!$E:$E,A14) -> 698.992 | F14: =E14*10 -> 6989.92 | G14: =SUMIFS('РПН по МО'!$E:$E,'РПН по МО'!$F:$F,A14) -> 28478 | H14: =IF(G14>0,G14/F14,"") -> 4.0741525 | I14: =IF(G14>0,ROUND(1+$I$3*$I$4/H14,4),"") -> 2.2589 | J14: =IF(D14="район",MIN(I14,2),IF(D14="город респ. значения",1,IF(D14="областной центр",1,1.5))) -> 2 | K14: 1.4339 | L14: =J14-K14 -> 0.5661 | M14: =IF(D14="город респ. значения","",H14) -> 4.0741525 | N14: =IF(D14="город респ. значения","",G14) -> 28478
A15: 1041 | B15: область Абай | C15: район Жаңасемей | D15: район | E15: =SUMIFS('Площадь МСХ'!$D:$D,'Площадь МСХ'!$E:$E,A15) -> 2754.401 | F15: =E15*10 -> 27544.01 | G15: =SUMIFS('РПН по МО'!$E:$E,'РПН по МО'!$F:$F,A15) -> 3768 | H15: =IF(G15>0,G15/F15,"") -> 0.13679925 | I15: =IF(G15>0,ROUND(1+$I$3*$I$4/H15,4),"") -> 38.4932 | J15: =IF(D15="район",MIN(I15,2),IF(D15="город респ. значения",1,IF(D15="областной центр",1,1.5))) -> 2 | K15: 1 | L15: =J15-K15 -> 1 | M15: =IF(D15="город респ. значения","",H15) -> 0.13679925 | N15: =IF(D15="город респ. значения","",G15) -> 3768
A16: 1042 | B16: область Абай | C16: Жарминский район | D16: район | E16: =SUMIFS('Площадь МСХ'!$D:$D,'Площадь МСХ'!$E:$E,A16) -> 2340.38 | F16: =E16*10 -> 23403.8 | G16: =SUMIFS('РПН по МО'!$E:$E,'РПН по МО'!$F:$F,A16) -> 31967 | H16: =IF(G16>0,G16/F16,"") -> 1.3658893 | I16: =IF(G16>0,ROUND(1+$I$3*$I$4/H16,4),"") -> 4.7551 | J16: =IF(D16="район",MIN(I16,2),IF(D16="город респ. значения",1,IF(D16="областной центр",1,1.5))) -> 2 | K16: 2 | L16: =J16-K16 -> 0 | M16: =IF(D16="город респ. значения","",H16) -> 1.3658893 | N16: =IF(D16="город респ. значения","",G16) -> 31967
A17: 1044 | B17: область Абай | C17: Кокпектинский район | D17: район | E17: =SUMIFS('Площадь МСХ'!$D:$D,'Площадь МСХ'!$E:$E,A17) -> 909.936 | F17: =E17*10 -> 9099.36 | G17: =SUMIFS('РПН по МО'!$E:$E,'РПН по МО'!$F:$F,A17) -> 11645 | H17: =IF(G17>0,G17/F17,"") -> 1.2797603 | I17: =IF(G17>0,ROUND(1+$I$3*$I$4/H17,4),"") -> 5.0078 | J17: =IF(D17="район",MIN(I17,2),IF(D17="город респ. значения",1,IF(D17="областной центр",1,1.5))) -> 2 | K17: 2 | L17: =J17-K17 -> 0 | M17: =IF(D17="город респ. значения","",H17) -> 1.2797603 | N17: =IF(D17="город респ. значения","",G17) -> 11645
A18: 1045 | B18: область Абай | C18: район Мақаншы | D18: район | E18: =SUMIFS('Площадь МСХ'!$D:$D,'Площадь МСХ'!$E:$E,A18) -> 1137.466 | F18: =E18*10 -> 11374.66 | G18: =SUMIFS('РПН по МО'!$E:$E,'РПН по МО'!$F:$F,A18) -> 22908 | H18: =IF(G18>0,G18/F18,"") -> 2.0139503 | I18: =IF(G18>0,ROUND(1+$I$3*$I$4/H18,4),"") -> 3.5468 | J18: =IF(D18="район",MIN(I18,2),IF(D18="город респ. значения",1,IF(D18="областной центр",1,1.5))) -> 2 | K18: 1.6934 | L18: =J18-K18 -> 0.3066 | M18: =IF(D18="город респ. значения","",H18) -> 2.0139503 | N18: =IF(D18="город респ. значения","",G18) -> 22908
A19: 1046 | B19: область Абай | C19: Урджарский район | D19: район | E19: =SUMIFS('Площадь МСХ'!$D:$D,'Площадь МСХ'!$E:$E,A19) -> 1203.906 | F19: =E19*10 -> 12039.06 | G19: =SUMIFS('РПН по МО'!$E:$E,'РПН по МО'!$F:$F,A19) -> 34662 | H19: =IF(G19>0,G19/F19,"") -> 2.8791284 | I19: =IF(G19>0,ROUND(1+$I$3*$I$4/H19,4),"") -> 2.7815 | J19: =IF(D19="район",MIN(I19,2),IF(D19="город респ. значения",1,IF(D19="областной центр",1,1.5))) -> 2 | K19: 1.6934 | L19: =J19-K19 -> 0.3066 | M19: =IF(D19="город респ. значения","",H19) -> 2.8791284 | N19: =IF(D19="город респ. значения","",G19) -> 34662
... A139: 4310 | B139: Кызылординская область | C139: Кызылорда | D139: областной центр | E139: =SUMIFS('Площадь МСХ'!$D:$D,'Площадь МСХ'!$E:$E,A139) -> 235.988 | F139: =E139*10 -> 2359.88 | G139: =SUMIFS('РПН по МО'!$E:$E,'РПН по МО'!$F:$F,A139) -> 378118 | H139: =IF(G139>0,G139/F139,"") -> 160.22764 | I139: =IF(G139>0,ROUND(1+$I$3*$I$4/H139,4),"") -> 1.032 | J139: =IF(D139="район",MIN(I139,2),IF(D139="город респ. значения",1,IF(D139="областной центр",1,1.5))) -> 1 | K139: 1 | L139: =J139-K139 -> 0 | M139: =IF(D139="город респ. значения","",H139) -> 160.22764 | N139: =IF(D139="город респ. значения","",G139) -> 378118
A140: 4319 | B140: Кызылординская область | C140: Байконыр | D140: моногород / малый город | E140: 5.498 | F140: =E140*10 -> 54.98 | G140: =SUMIFS('РПН по МО'!$E:$E,'РПН по МО'!$F:$F,A140) -> 39604 | H140: =IF(G140>0,G140/F140,"") -> 720.33467 | I140: =IF(G140>0,ROUND(1+$I$3*$I$4/H140,4),"") -> 1.0071 | J140: =IF(D140="район",MIN(I140,2),IF(D140="город респ. значения",1,IF(D140="областной центр",1,1.5))) -> 1.5 | K140: 1.5 | L140: =J140-K140 -> 0 | M140: =IF(D140="город респ. значения","",H140) -> 720.33467 | N140: =IF(D140="город респ. значения","",G140) -> 39604
A141: 4332 | B141: Кызылординская область | C141: Аральский район | D141: район | E141: =SUMIFS('Площадь МСХ'!$D:$D,'Площадь МСХ'!$E:$E,A141) -> 5521.274 | F141: =E141*10 -> 55212.74 | G141: =SUMIFS('РПН по МО'!$E:$E,'РПН по МО'!$F:$F,A141) -> 71158 | H141: =IF(G141>0,G141/F141,"") -> 1.2887968 | I141: =IF(G141>0,ROUND(1+$I$3*$I$4/H141,4),"") -> 4.9797 | J141: =IF(D141="район",MIN(I141,2),IF(D141="город респ. значения",1,IF(D141="областной центр",1,1.5))) -> 2 | K141: 2 | L141: =J141-K141 -> 0 | M141: =IF(D141="город респ. значения","",H141) -> 1.2887968 | N141: =IF(D141="город респ. значения","",G141) -> 71158
A142: 4336 | B142: Кызылординская область | C142: Жалагашский район | D142: район | E142: =SUMIFS('Площадь МСХ'!$D:$D,'Площадь МСХ'!$E:$E,A142) -> 2293.226 | F142: =E142*10 -> 22932.26 | G142: =SUMIFS('РПН по МО'!$E:$E,'РПН по МО'!$F:$F,A142) -> 31296 | H142: =IF(G142>0,G142/F142,"") -> 1.364715 | I142: =IF(G142>0,ROUND(1+$I$3*$I$4/H142,4),"") -> 4.7583 | J142: =IF(D142="район",MIN(I142,2),IF(D142="город респ. значения",1,IF(D142="областной центр",1,1.5))) -> 2 | K142: 2 | L142: =J142-K142 -> 0 | M142: =IF(D142="город респ. значения","",H142) -> 1.364715 | N142: =IF(D142="город респ. значения","",G142) -> 31296
A143: 4340 | B143: Кызылординская область | C143: Жанакорганский район | D143: район | E143: =SUMIFS('Площадь МСХ'!$D:$D,'Площадь МСХ'!$E:$E,A143) -> 1543.396 | F143: =E143*10 -> 15433.96 | G143: =SUMIFS('РПН по МО'!$E:$E,'РПН по МО'!$F:$F,A143) -> 72967 | H143: =IF(G143>0,G143/F143,"") -> 4.7276914 | I143: =IF(G143>0,ROUND(1+$I$3*$I$4/H143,4),"") -> 2.0849 | J143: =IF(D143="район",MIN(I143,2),IF(D143="город респ. значения",1,IF(D143="областной центр",1,1.5))) -> 2 | K143: 1.392 | L143: =J143-K143 -> 0.608 | M143: =IF(D143="город респ. значения","",H143) -> 4.7276914 | N143: =IF(D143="город респ. значения","",G143) -> 72967
A144: 4344 | B144: Кызылординская область | C144: Казалинский район | D144: район | E144: =SUMIFS('Площадь МСХ'!$D:$D,'Площадь МСХ'!$E:$E,A144) -> 3759.706 | F144: =E144*10 -> 37597.06 | G144: =SUMIFS('РПН по МО'!$E:$E,'РПН по МО'!$F:$F,A144) -> 76791 | H144: =IF(G144>0,G144/F144,"") -> 2.0424735 | I144: =IF(G144>0,ROUND(1+$I$3*$I$4/H144,4),"") -> 3.5112 | J144: =IF(D144="район",MIN(I144,2),IF(D144="город респ. значения",1,IF(D144="областной центр",1,1.5))) -> 2 | K144: 1.9817 | L144: =J144-K144 -> 0.0183 | M144: =IF(D144="город респ. значения","",H144) -> 2.0424735 | N144: =IF(D144="город респ. значения","",G144) -> 76791
A145: 4346 | B145: Кызылординская область | C145: Кармакшинский район | D145: район | E145: =SUMIFS('Площадь МСХ'!$D:$D,'Площадь МСХ'!$E:$E,A145) -> 3104.07 | F145: =E145*10 -> 31040.7 | G145: =SUMIFS('РПН по МО'!$E:$E,'РПН по МО'!$F:$F,A145) -> 30558 | H145: =IF(G145>0,G145/F145,"") -> 0.98444945 | I145: =IF(G145>0,ROUND(1+$I$3*$I$4/H145,4),"") -> 6.2101 | J145: =IF(D145="район",MIN(I145,2),IF(D145="город респ. значения",1,IF(D145="областной центр",1,1.5))) -> 2 | K145: 2 | L145: =J145-K145 -> 0 | M145: =IF(D145="город респ. значения","",H145) -> 0.98444945 | N145: =IF(D145="город респ. значения","",G145) -> 30558
A146: 4348 | B146: Кызылординская область | C146: Сырдарьинский район | D146: район | E146: =SUMIFS('Площадь МСХ'!$D:$D,'Площадь МСХ'!$E:$E,A146) -> 2904.533 | F146: =E146*10 -> 29045.33 | G146: =SUMIFS('РПН по МО'!$E:$E,'РПН по МО'!$F:$F,A146) -> 33538 | H146: =IF(G146>0,G146/F146,"") -> 1.1546779 | I146: =IF(G146>0,ROUND(1+$I$3*$I$4/H146,4),"") -> 5.442 | J146: =IF(D146="район",MIN(I146,2),IF(D146="город респ. значения",1,IF(D146="областной центр",1,1.5))) -> 2 | K146: 2 | L146: =J146-K146 -> 0 | M146: =IF(D146="город респ. значения","",H146) -> 1.1546779 | N146: =IF(D146="город респ. значения","",G146) -> 33538
A147: 4352 | B147: Кызылординская область | C147: Шиелийский район | D147: район | E147: =SUMIFS('Площадь МСХ'!$D:$D,'Площадь МСХ'!$E:$E,A147) -> 3239.755 | F147: =E147*10 -> 32397.55 | G147: =SUMIFS('РПН по МО'!$E:$E,'РПН по МО'!$F:$F,A147) -> 77807 | H147: =IF(G147>0,G147/F147,"") -> 2.4016322 | I147: =IF(G147>0,ROUND(1+$I$3*$I$4/H147,4),"") -> 3.1356 | J147: =IF(D147="район",MIN(I147,2),IF(D147="город респ. значения",1,IF(D147="областной центр",1,1.5))) -> 2 | K147: 1.7795 | L147: =J147-K147 -> 0.2205 | M147: =IF(D147="город респ. значения","",H147) -> 2.4016322 | N147: =IF(D147="город респ. значения","",G147) -> 77807
A148: 4710 | B148: Мангистауская область | C148: Актау | D148: областной центр | E148: =SUMIFS('Площадь МСХ'!$D:$D,'Площадь МСХ'!$E:$E,A148) -> 29.849 | F148: =E148*10 -> 298.49 | G148: =SUMIFS('РПН по МО'!$E:$E,'РПН по МО'!$F:$F,A148) -> 347110 | H148: =IF(G148>0,G148/F148,"") -> 1162.8865 | I148: =IF(G148>0,ROUND(1+$I$3*$I$4/H148,4),"") -> 1.0044 | J148: =IF(D148="район",MIN(I148,2),IF(D148="город респ. значения",1,IF(D148="областной центр",1,1.5))) -> 1 | K148: 1 | L148: =J148-K148 -> 0 | M148: =IF(D148="город респ. значения","",H148) -> 1162.8865 | N148: =IF(D148="город респ. значения","",G148) -> 347110
A149: 4718 | B149: Мангистауская область | C149: Жанаозен | D149: моногород / малый город | E149: =SUMIFS('Площадь МСХ'!$D:$D,'Площадь МСХ'!$E:$E,A149) -> 51.549 | F149: =E149*10 -> 515.49 | G149: =SUMIFS('РПН по МО'!$E:$E,'РПН по МО'!$F:$F,A149) -> 146473 | H149: =IF(G149>0,G149/F149,"") -> 284.14324 | I149: =IF(G149>0,ROUND(1+$I$3*$I$4/H149,4),"") -> 1.0181 | J149: =IF(D149="район",MIN(I149,2),IF(D149="город респ. значения",1,IF(D149="областной центр",1,1.5))) -> 1.5 | K149: 1.5 | L149: =J149-K149 -> 0 | M149: =IF(D149="город респ. значения","",H149) -> 284.14324 | N149: =IF(D149="город респ. значения","",G149) -> 146473
A150: 4736 | B150: Мангистауская область | C150: Бейнеуский район | D150: район | E150: =SUMIFS('Площадь МСХ'!$D:$D,'Площадь МСХ'!$E:$E,A150) -> 4051.933 | F150: =E150*10 -> 40519.33 | G150: =SUMIFS('РПН по МО'!$E:$E,'РПН по МО'!$F:$F,A150) -> 56835 | H150: =IF(G150>0,G150/F150,"") -> 1.4026639 | I150: =IF(G150>0,ROUND(1+$I$3*$I$4/H150,4),"") -> 4.6566 | J150: =IF(D150="район",MIN(I150,2),IF(D150="город респ. значения",1,IF(D150="областной центр",1,1.5))) -> 2 | K150: 2 | L150: =J150-K150 -> 0 | M150: =IF(D150="город респ. значения","",H150) -> 1.4026639 | N150: =IF(D150="город респ. значения","",G150) -> 56835
A151: 4742 | B151: Мангистауская область | C151: Каракиянский район | D151: район | E151: =SUMIFS('Площадь МСХ'!$D:$D,'Площадь МСХ'!$E:$E,A151) -> 6483.6369 | F151: =E151*10 -> 64836.369 | G151: =SUMIFS('РПН по МО'!$E:$E,'РПН по МО'!$F:$F,A151) -> 38031 | H151: =IF(G151>0,G151/F151,"") -> 0.58656894 | I151: =IF(G151>0,ROUND(1+$I$3*$I$4/H151,4),"") -> 9.7441 | J151: =IF(D151="район",MIN(I151,2),IF(D151="город респ. значения",1,IF(D151="областной центр",1,1.5))) -> 2 | K151: 2 | L151: =J151-K151 -> 0 | M151: =IF(D151="город респ. значения","",H151) -> 0.58656894 | N151: =IF(D151="город респ. значения","",G151) -> 38031
A152: 4746 | B152: Мангистауская область | C152: Мангистауский район | D152: район | E152: =SUMIFS('Площадь МСХ'!$D:$D,'Площадь МСХ'!$E:$E,A152) -> 4602.2253 | F152: =E152*10 -> 46022.253 | G152: =SUMIFS('РПН по МО'!$E:$E,'РПН по МО'!$F:$F,A152) -> 30621 | H152: =IF(G152>0,G152/F152,"") -> 0.66535204 | I152: =IF(G152>0,ROUND(1+$I$3*$I$4/H152,4),"") -> 8.7088 | J152: =IF(D152="район",MIN(I152,2),IF(D152="город респ. значения",1,IF(D152="областной центр",1,1.5))) -> 2 | K152: 2 | L152: =J152-K152 -> 0 | M152: =IF(D152="город респ. значения","",H152) -> 0.66535204 | N152: =IF(D152="город респ. значения","",G152) -> 30621
... A208: 6348 | B208: Восточно-Казахстанская область | C208: район Алтай | D208: район | E208: =SUMIFS('Площадь МСХ'!$D:$D,'Площадь МСХ'!$E:$E,A208) -> 1056.096 | F208: =E208*10 -> 10560.96 | G208: =SUMIFS('РПН по МО'!$E:$E,'РПН по МО'!$F:$F,A208) -> 57519 | H208: =IF(G208>0,G208/F208,"") -> 5.4463799 | I208: =IF(G208>0,ROUND(1+$I$3*$I$4/H208,4),"") -> 1.9417 | J208: =IF(D208="район",MIN(I208,2),IF(D208="город респ. значения",1,IF(D208="областной центр",1,1.5))) -> 1.9417 | K208: 1.3549 | L208: =J208-K208 -> 0.5868 | M208: =IF(D208="город респ. значения","",H208) -> 5.4463799 | N208: =IF(D208="город респ. значения","",G208) -> 57519
A209: 6352 | B209: Восточно-Казахстанская область | C209: Курчумский район | D209: район | E209: =SUMIFS('Площадь МСХ'!$D:$D,'Площадь МСХ'!$E:$E,A209) -> 1216.969 | F209: =E209*10 -> 12169.69 | G209: =SUMIFS('РПН по МО'!$E:$E,'РПН по МО'!$F:$F,A209)-G211 -> 13370 | H209: =IF(G209>0,G209/F209,"") -> 1.0986311 | I209: =IF(G209>0,ROUND(1+$I$3*$I$4/H209,4),"") -> 5.6686 | J209: =IF(D209="район",MIN(I209,2),IF(D209="город респ. значения",1,IF(D209="областной центр",1,1.5))) -> 2 | K209: 2 | L209: =J209-K209 -> 0 | M209: =IF(D209="город респ. значения","",H209) -> 1.0986311 | N209: =IF(D209="город респ. значения","",G209) -> 13370
A210: 6354 | B210: Восточно-Казахстанская область | C210: Катон-Карагайский район | D210: район | E210: =SUMIFS('Площадь МСХ'!$D:$D,'Площадь МСХ'!$E:$E,A210) -> 940.777 | F210: =E210*10 -> 9407.77 | G210: =SUMIFS('РПН по МО'!$E:$E,'РПН по МО'!$F:$F,A210) -> 8639 | H210: =IF(G210>0,G210/F210,"") -> 0.9182835 | I210: =IF(G210>0,ROUND(1+$I$3*$I$4/H210,4),"") -> 6.5855 | J210: =IF(D210="район",MIN(I210,2),IF(D210="город респ. значения",1,IF(D210="областной центр",1,1.5))) -> 2 | K210: 2 | L210: =J210-K210 -> 0 | M210: =IF(D210="город респ. значения","",H210) -> 0.9182835 | N210: =IF(D210="город респ. значения","",G210) -> 8639
A211: 6355 | B211: Восточно-Казахстанская область | C211: район Марқакөл | D211: район | E211: =SUMIFS('Площадь МСХ'!$D:$D,'Площадь МСХ'!$E:$E,A211) -> 1102.917 | F211: =E211*10 -> 11029.17 | G211: ='Курчум – Марқакөл'!C22 -> 6285 | H211: =IF(G211>0,G211/F211,"") -> 0.56985249 | I211: =IF(G211>0,ROUND(1+$I$3*$I$4/H211,4),"") -> 10.0006 | J211: =IF(D211="район",MIN(I211,2),IF(D211="город респ. значения",1,IF(D211="областной центр",1,1.5))) -> 2 | K211: 2 | L211: =J211-K211 -> 0 | M211: =IF(D211="город респ. значения","",H211) -> 0.56985249 | N211: =IF(D211="город респ. значения","",G211) -> 6285
A212: 6356 | B212: Восточно-Казахстанская область | C212: район Самар | D212: район | E212: =SUMIFS('Площадь МСХ'!$D:$D,'Площадь МСХ'!$E:$E,A212) -> 547.6 | F212: =E212*10 -> 5476 | G212: =SUMIFS('РПН по МО'!$E:$E,'РПН по МО'!$F:$F,A212) -> 10645 | H212: =IF(G212>0,G212/F212,"") -> 1.9439372 | I212: =IF(G212>0,ROUND(1+$I$3*$I$4/H212,4),"") -> 3.6385 | J212: =IF(D212="район",MIN(I212,2),IF(D212="город респ. значения",1,IF(D212="областной центр",1,1.5))) -> 2 | K212: 1.9345 | L212: =J212-K212 -> 0.0655 | M212: =IF(D212="город респ. значения","",H212) -> 1.9439372 | N212: =IF(D212="город респ. значения","",G212) -> 10645
A213: 6358 | B213: Восточно-Казахстанская область | C213: Тарбагатайский район | D213: район | E213: =SUMIFS('Площадь МСХ'!$D:$D,'Площадь МСХ'!$E:$E,A213) -> 1017 | F213: =E213*10 -> 10170 | G213: =SUMIFS('РПН по МО'!$E:$E,'РПН по МО'!$F:$F,A213) -> 16946 | H213: =IF(G213>0,G213/F213,"") -> 1.6662734 | I213: =IF(G213>0,ROUND(1+$I$3*$I$4/H213,4),"") -> 4.0781 | J213: =IF(D213="район",MIN(I213,2),IF(D213="город респ. значения",1,IF(D213="областной центр",1,1.5))) -> 2 | K213: 2 | L213: =J213-K213 -> 0 | M213: =IF(D213="город респ. значения","",H213) -> 1.6662734 | N213: =IF(D213="город респ. значения","",G213) -> 16946
A214: 6362 | B214: Восточно-Казахстанская область | C214: Уланский район | D214: район | E214: =SUMIFS('Площадь МСХ'!$D:$D,'Площадь МСХ'!$E:$E,A214) -> 962.481 | F214: =E214*10 -> 9624.81 | G214: =SUMIFS('РПН по МО'!$E:$E,'РПН по МО'!$F:$F,A214) -> 28227 | H214: =IF(G214>0,G214/F214,"") -> 2.9327332 | I214: =IF(G214>0,ROUND(1+$I$3*$I$4/H214,4),"") -> 2.7489 | J214: =IF(D214="район",MIN(I214,2),IF(D214="город респ. значения",1,IF(D214="областной центр",1,1.5))) -> 2 | K214: 1.5835 | L214: =J214-K214 -> 0.4165 | M214: =IF(D214="город респ. значения","",H214) -> 2.9327332 | N214: =IF(D214="город респ. значения","",G214) -> 28227
A215: 6363 | B215: Восточно-Казахстанская область | C215: район Үлкен Нарын | D215: район | E215: =SUMIFS('Площадь МСХ'!$D:$D,'Площадь МСХ'!$E:$E,A215) -> 378.298 | F215: =E215*10 -> 3782.98 | G215: =SUMIFS('РПН по МО'!$E:$E,'РПН по МО'!$F:$F,A215) -> 9530 | H215: =IF(G215>0,G215/F215,"") -> 2.519178 | I215: =IF(G215>0,ROUND(1+$I$3*$I$4/H215,4),"") -> 3.036 | J215: =IF(D215="район",MIN(I215,2),IF(D215="город респ. значения",1,IF(D215="областной центр",1,1.5))) -> 2 | K215: 2 | L215: =J215-K215 -> 0 | M215: =IF(D215="город респ. значения","",H215) -> 2.519178 | N215: =IF(D215="город респ. значения","",G215) -> 9530
...

Sheet РПН по МО
A1: Прикреплённое население по МО (ЦС «РПН» на 01.01.2026), район МО и источник данных
A3: № | B3: Область (РПН) | C3: Наименование МО | D3: БИН | E3: Прикреплённое население | F3: Код района | G3: Район (по коду) | H3: КАТО (18.09.2026) | I3: Влияет на Кплотн | J3: Источник данных (примечание) | K3: Ссылка
A4: 1 | B4: АБАЙ | C4: "Коммунальное госудаственное предприятие на праве хозяйственного ведения "Аксуатская районная больница" управления здравоохранения области Абай" | D4: 80640003228 | E4: 16638 | F4: 1034 | G4: =IFERROR(INDEX('Расчет Кплотн'!$C:$C,MATCH(F4,'Расчет Кплотн'!$A:$A,0)),"код не найден") -> район Ақсуат | H4: 103430100 | I4: да | J4: КАТО местонахождения МО по ЦС «РПН» (выгрузка от 04.10.2026), соответствует КАТО 18.09.2026
A5: 2 | B5: АБАЙ | C5: Учреждение "Семейная амбулатория "Азат" | D5: 970440001312 | E5: 3051 | F5: 1042 | G5: =IFERROR(INDEX('Расчет Кплотн'!$C:$C,MATCH(F5,'Расчет Кплотн'!$A:$A,0)),"код не найден") -> Жарминский район | H5: 104230100 | I5: да | J5: КАТО местонахождения МО по ЦС «РПН» (выгрузка от 04.10.2026), соответствует КАТО 18.09.2026
A6: 3 | B6: АБАЙ | C6: У-е "Сельская амбулатория "Гармония" | D6: 980240018349 | E6: 1800 | F6: 1041 | G6: =IFERROR(INDEX('Расчет Кплотн'!$C:$C,MATCH(F6,'Расчет Кплотн'!$A:$A,0)),"код не найден") -> район Жаңасемей | I6: да | J6: КАТО в ЦС «РПН» не указан; район Жаңасемей (по наименованию и КАТО 18.09.2026)
A7: 4 | B7: АБАЙ | C7: У-е "Поликлиника "Хаким" | D7: 970340000417 | E7: 11712 | F7: 1010 | G7: =IFERROR(INDEX('Расчет Кплотн'!$C:$C,MATCH(F7,'Расчет Кплотн'!$A:$A,0)),"код не найден") -> Семей | H7: 101010000 | I7: нет | J7: КАТО местонахождения МО по ЦС «РПН» (выгрузка от 04.10.2026), соответствует КАТО 18.09.2026
A8: 5 | B8: АБАЙ | C8: У-е "Консультативно-диагностическая поликлиника № 3 города Семей" | D8: 130640005216 | E8: 19280 | F8: 1010 | G8: =IFERROR(INDEX('Расчет Кплотн'!$C:$C,MATCH(F8,'Расчет Кплотн'!$A:$A,0)),"код не найден") -> Семей | H8: 101010000 | I8: нет | J8: КАТО местонахождения МО по ЦС «РПН» (выгрузка от 04.10.2026), соответствует КАТО 18.09.2026
A9: 6 | B9: АБАЙ | C9: ТОО "Семейская железнодорожная больница" | D9: 180440021408 | E9: 35836 | F9: 1010 | G9: =IFERROR(INDEX('Расчет Кплотн'!$C:$C,MATCH(F9,'Расчет Кплотн'!$A:$A,0)),"код не найден") -> Семей | H9: 101010000 | I9: нет | J9: КАТО местонахождения МО по ЦС «РПН» (выгрузка от 04.10.2026), соответствует КАТО 18.09.2026
A10: 7 | B10: АБАЙ | C10: ТОО "Поликлиника №6 города Семей" | D10: 130740008581 | E10: 40134 | F10: 1010 | G10: =IFERROR(INDEX('Расчет Кплотн'!$C:$C,MATCH(F10,'Расчет Кплотн'!$A:$A,0)),"код не найден") -> Семей | H10: 101010000 | I10: нет | J10: КАТО местонахождения МО по ЦС «РПН» (выгрузка от 04.10.2026), соответствует КАТО 18.09.2026
A11: 8 | B11: АБАЙ | C11: ТОО "Клиника iv plus" | D11: 90940007481 | E11: 6545 | F11: 1010 | G11: =IFERROR(INDEX('Расчет Кплотн'!$C:$C,MATCH(F11,'Расчет Кплотн'!$A:$A,0)),"код не найден") -> Семей | H11: 101010000 | I11: нет | J11: КАТО местонахождения МО по ЦС «РПН» (выгрузка от 04.10.2026), соответствует КАТО 18.09.2026
A12: 9 | B12: АБАЙ | C12: ТОО "Қазығұл" | D12: 970140005506 | E12: 12766 | F12: 1036 | G12: =IFERROR(INDEX('Расчет Кплотн'!$C:$C,MATCH(F12,'Расчет Кплотн'!$A:$A,0)),"код не найден") -> Аягозский район | H12: 103620100 | I12: да | J12: КАТО местонахождения МО по ЦС «РПН» (выгрузка от 04.10.2026), соответствует КАТО 18.09.2026
A13: 10 | B13: АБАЙ | C13: ТОО "Жан-Ер" | D13: 51140004661 | E13: 9433 | F13: 1010 | G13: =IFERROR(INDEX('Расчет Кплотн'!$C:$C,MATCH(F13,'Расчет Кплотн'!$A:$A,0)),"код не найден") -> Семей | H13: 101010000 | I13: нет | J13: КАТО местонахождения МО по ЦС «РПН» (выгрузка от 04.10.2026), соответствует КАТО 18.09.2026
A14: 11 | B14: АБАЙ | C14: МУ "Центральная смотровая поликлиника" | D14: 50740001874 | E14: 17699 | F14: 1010 | G14: =IFERROR(INDEX('Расчет Кплотн'!$C:$C,MATCH(F14,'Расчет Кплотн'!$A:$A,0)),"код не найден") -> Семей | H14: 101010000 | I14: нет | J14: КАТО местонахождения МО по ЦС «РПН» (выгрузка от 04.10.2026), соответствует КАТО 18.09.2026
A15: 12 | B15: АБАЙ | C15: Медицинское учреждение "Поликлиника № 8 города Семей" | D15: 191140014657 | E15: 9227 | F15: 1010 | G15: =IFERROR(INDEX('Расчет Кплотн'!$C:$C,MATCH(F15,'Расчет Кплотн'!$A:$A,0)),"код не найден") -> Семей | H15: 101010000 | I15: нет | J15: КАТО местонахождения МО по ЦС «РПН» (выгрузка от 04.10.2026), соответствует КАТО 18.09.2026
A16: 13 | B16: АБАЙ | C16: Медицинское У-е "Победа" | D16: 980640000350 | E16: 9841 | F16: 1010 | G16: =IFERROR(INDEX('Расчет Кплотн'!$C:$C,MATCH(F16,'Расчет Кплотн'!$A:$A,0)),"код не найден") -> Семей | H16: 101010000 | I16: нет | J16: КАТО местонахождения МО по ЦС «РПН» (выгрузка от 04.10.2026), соответствует КАТО 18.09.2026
A17: 14 | B17: АБАЙ | C17: Коммунальное государственное предприятие на праве хозяйственного ведения «Многопрофильная центральная районная больница Урджарского района» управления здравоохранения области Абай | D17: 80640010558 | E17: 34662 | F17: 1046 | G17: =IFERROR(INDEX('Расчет Кплотн'!$C:$C,MATCH(F17,'Расчет Кплотн'!$A:$A,0)),"код не найден") -> Урджарский район | H17: 104630100 | I17: да | J17: КАТО местонахождения МО по ЦС «РПН» (выгрузка от 04.10.2026), соответствует КАТО 18.09.2026
A18: 15 | B18: АБАЙ | C18: Коммунальное государственное предприятие на праве хозяйственного ведения «Бескарагайская районная больница» управления здравоохранения области Абай | D18: 80640010372 | E18: 14632 | F18: 1038 | G18: =IFERROR(INDEX('Расчет Кплотн'!$C:$C,MATCH(F18,'Расчет Кплотн'!$A:$A,0)),"код не найден") -> Бескарагайский район | H18: 103830100 | I18: да | J18: КАТО местонахождения МО по ЦС «РПН» (выгрузка от 04.10.2026), соответствует КАТО 18.09.2026
... A23: 20 | B23: АБАЙ | C23: КГП на ПХВ «Центр первичной медико-санитарной помощи № 10 города Семей» управления здравоохранения области Абай | D23: 990340000758 | E23: 13963 | F23: 1010 | G23: =IFERROR(INDEX('Расчет Кплотн'!$C:$C,MATCH(F23,'Расчет Кплотн'!$A:$A,0)),"код не найден") -> Семей | H23: 101010000 | I23: нет | J23: КАТО местонахождения МО по ЦС «РПН» (выгрузка от 04.10.2026), соответствует КАТО 18.09.2026
A24: 21 | B24: АБАЙ | C24: КГП на ПХВ "Больница района Жаңасемей" управления здравоохранения области Абай | D24: 80740000693 | E24: 1968 | F24: 1041 | G24: =IFERROR(INDEX('Расчет Кплотн'!$C:$C,MATCH(F24,'Расчет Кплотн'!$A:$A,0)),"код не найден") -> район Жаңасемей | I24: да | J24: КАТО в ЦС «РПН» не указан; по наименованию МО
A25: 22 | B25: АБАЙ | C25: КГП на ПХВ "Бородулихинская районная больница" управления здравоохранения области Абай | D25: 80640019859 | E25: 28478 | F25: 1040 | G25: =IFERROR(INDEX('Расчет Кплотн'!$C:$C,MATCH(F25,'Расчет Кплотн'!$A:$A,0)),"код не найден") -> Бородулихинский район | H25: 104030100 | I25: да | J25: КАТО местонахождения МО по ЦС «РПН» (выгрузка от 04.10.2026), соответствует КАТО 18.09.2026
